<sdf version='1.9'>
    <plugin filename="libignition-gazebo-sensors-system.so" name="ignition::gazebo::systems::Sensors">
        <render_engine>ogre2</render_engine>
    </plugin>
    <plugin filename="libignition-gazebo-imu-system.so" name="ignition::gazebo::systems::Imu"/>
    <model name='limo_four_diff'>
        <link name='base_footprint'>
            <inertial>
                <pose>0.007904637105296531 0 0.1494082089867692 0 0 0</pose>
                <mass>2.3656999999999999</mass>
                <inertia>
                    <ixx>0.24030687149258151</ixx>
                    <ixy>0</ixy>
                    <ixz>8.7133508052584466e-05</ixz>
                    <iyy>0.96192555477871244</iyy>
                    <iyz>0</iyz>
                    <izz>0.96162078328613076</izz>
                </inertia>
            </inertial>
            <collision name='base_footprint_fixed_joint_lump__base_link_collision'>
                <pose>0 0 0.15 0 0 0</pose>
                <geometry>
                    <box>
                        <size>0.13 0.12 0.1</size>
                    </box>
                </geometry>
            </collision>
            <collision name='base_footprint_fixed_joint_lump__depth_camera_collision_collision_1'>
                <pose>0.08400000000000001 0 0.18 0 0 0</pose>
                <geometry>
                    <box>
                        <size>0.02 0.06 0.015</size>
                    </box>
                </geometry>
            </collision>
            <collision name='base_footprint_fixed_joint_lump__imu_collision_collision_2'>
                <pose>0 0 0.04999999999999999 0 0 0</pose>
                <geometry>
                    <box>
                        <size>0.001 0.001 0.001</size>
                    </box>
                </geometry>
            </collision>
            <collision name='base_footprint_fixed_joint_lump__laser_collision_collision_3'>
                <pose>0.103 0 0.116 0 0 0</pose>
                <geometry>
                    <cylinder>
                        <length>0.016</length>
                        <radius>0.032000000000000001</radius>
                    </cylinder>
                </geometry>
            </collision>
            <visual name='base_footprint_fixed_joint_lump__base_link_visual'>
                <pose>0 0 0 0 0 1.57</pose>
                <geometry>
                    <mesh>
                        <scale>1 1 1</scale>
                        <uri>meshes/limo_base.dae</uri>
                    </mesh>
                </geometry>
            </visual>
            <visual name='base_footprint_fixed_joint_lump__depth_camera_visual_visual_1'>
                <pose>0.08400000000000001 0 0.18 0 0 0</pose>
                <geometry>
                    <box>
                        <size>0.02 0.06 0.015</size>
                    </box>
                </geometry>
                <material>
                    <diffuse>0 0 0 1</diffuse>
                    <ambient>0 0 0 1</ambient>
                </material>
            </visual>
            <visual name='base_footprint_fixed_joint_lump__imu_visual_visual_2'>
                <pose>0 0 0.04999999999999999 0 0 0</pose>
                <geometry>
                    <box>
                        <size>0.001 0.001 0.001</size>
                    </box>
                </geometry>
                <material>
                    <diffuse>0 0 0 1</diffuse>
                    <ambient>0 0 0 1</ambient>
                </material>
            </visual>
            <visual name='base_footprint_fixed_joint_lump__laser_visual_visual_3'>
                <pose>0.103 0 0.116 0 0 0</pose>
                <geometry>
                    <cylinder>
                        <length>0.01</length>
                        <radius>0.02</radius>
                    </cylinder>
                </geometry>
                <material>
                    <diffuse>0 0 0 1</diffuse>
                    <ambient>0 0 0 1</ambient>
                </material>
            </visual>
            <sensor name='sensor_camera' type='depth_camera'>
                <topic>/limo/depth/image_raw</topic>
                <always_on>true</always_on>
                <visualize>true</visualize>
                <update_rate>10</update_rate>
                <camera name='head'>
                    <cameraInfoTopic>/limo/color/camera_info</cameraInfoTopic>
                    <horizontal_fov>1.3962634</horizontal_fov>
                    <image>
                        <width>640</width>
                        <height>480</height>
                        <format>R8G8B8</format>
                    </image>
                    <clip>
                        <near>0.02</near>
                        <far>300</far>
                    </clip>
                    <lens>

                    </lens>
                </camera>
                <pose relative_to="depth_link">0.084 0 0.18 0 -0 0</pose>
            </sensor>
            <gravity>true</gravity>
            <sensor name='imu_sensor' type='imu'>
                <topic>/limo/imu</topic>
                <always_on>true</always_on>
                <update_rate>100</update_rate>
                <visualize>true</visualize>
                <pose relative_to="imu_link">0 0 0.05 0 -0 0</pose>
            </sensor>
            <sensor name='laser_sensor' type='gpu_lidar'>
                <topic>/limo/scan</topic>
                <visualize>false</visualize>
                <update_rate>8</update_rate>
                <ray>
                    <scan>
                        <horizontal>
                            <samples>720</samples>
                            <resolution>1</resolution>
                            <min_angle>-2.0943950400000002</min_angle>
                            <max_angle>2.0943950400000002</max_angle>
                        </horizontal>
                    </scan>
                    <range>
                        <min>0.050000000000000003</min>
                        <max>8</max>
                        <resolution>0.01</resolution>
                    </range>
                    <noise>
                        <type>gaussian</type>
                        <mean>0</mean>
                        <stddev>0.01</stddev>
                    </noise>
                </ray>
                <pose relative_to="laser_link">0.103 0 0.116 0 -0 0</pose>
            </sensor>
        </link>
        <joint name='front_left_wheel' type='revolute'>
            <pose relative_to='base_footprint'>0.1 0.065 0.04999999999999999 0 0 0</pose>
            <parent>base_footprint</parent>
            <child>front_left_wheel_link</child>
            <axis>
                <xyz>0 1 0</xyz>
                <limit>
                    <lower>-10000000000000000</lower>
                    <upper>10000000000000000</upper>
                </limit>
                <dynamics>
                    <spring_reference>0</spring_reference>
                    <spring_stiffness>0</spring_stiffness>
                </dynamics>
            </axis>
            <physics>
                <ode>
                    <limit>
                        <cfm>0</cfm>
                        <erp>0.20000000000000001</erp>
                    </limit>
                </ode>
            </physics>
        </joint>
        <link name='front_left_wheel_link'>
            <pose relative_to='front_left_wheel'>0 0 0 0 0 0</pose>
            <inertial>
                <pose>0 0 0 0 0 0</pose>
                <mass>0.5</mass>
                <inertia>
                    <ixx>0.01055</ixx>
                    <ixy>0</ixy>
                    <ixz>0</ixz>
                    <iyy>0.00075000000000000002</iyy>
                    <iyz>0</iyz>
                    <izz>0.01055</izz>
                </inertia>
            </inertial>
            <collision name='front_left_wheel_link_collision'>
                <pose>0 0.0225 0 1.57 0 0</pose>
                <geometry>
                    <cylinder>
                        <length>0.044999999999999998</length>
                        <radius>0.044999999999999998</radius>
                    </cylinder>
                </geometry>
            </collision>
            <visual name='front_left_wheel_link_visual'>
                <pose>0 0 0 0 0 0</pose>
                <geometry>
                    <mesh>
                        <scale>1 1 1</scale>
                        <uri>meshes/limo_wheel.dae</uri>
                    </mesh>
                </geometry>
            </visual>
        </link>
        <joint name='front_right_wheel' type='revolute'>
            <pose relative_to='base_footprint'>0.1 -0.065 0.04999999999999999 3.14159 0 0</pose>
            <parent>base_footprint</parent>
            <child>front_right_wheel_link</child>
            <axis>
                <xyz>0 -1 0</xyz>
                <limit>
                    <lower>-10000000000000000</lower>
                    <upper>10000000000000000</upper>
                </limit>
                <dynamics>
                    <spring_reference>0</spring_reference>
                    <spring_stiffness>0</spring_stiffness>
                </dynamics>
            </axis>
            <physics>
                <ode>
                    <limit>
                        <cfm>0</cfm>
                        <erp>0.20000000000000001</erp>
                    </limit>
                </ode>
            </physics>
        </joint>
        <link name='front_right_wheel_link'>
            <pose relative_to='front_right_wheel'>0 0 0 0 0 0</pose>
            <inertial>
                <pose>0 0 0 0 0 0</pose>
                <mass>0.5</mass>
                <inertia>
                    <ixx>0.01055</ixx>
                    <ixy>0</ixy>
                    <ixz>0</ixz>
                    <iyy>0.00075000000000000002</iyy>
                    <iyz>0</iyz>
                    <izz>0.01055</izz>
                </inertia>
            </inertial>
            <collision name='front_right_wheel_link_collision'>
                <pose>0 0.0225 0 1.57 0 0</pose>
                <geometry>
                    <cylinder>
                        <length>0.044999999999999998</length>
                        <radius>0.044999999999999998</radius>
                    </cylinder>
                </geometry>
            </collision>
            <visual name='front_right_wheel_link_visual'>
                <pose>0 0 0 0 0 0</pose>
                <geometry>
                    <mesh>
                        <scale>1 1 1</scale>
                        <uri>meshes/limo_wheel.dae</uri>
                    </mesh>
                </geometry>
            </visual>
        </link>
        <joint name='rear_left_wheel' type='revolute'>
            <pose relative_to='base_footprint'>-0.1 0.065 0.04999999999999999 0 0 0</pose>
            <parent>base_footprint</parent>
            <child>rear_left_wheel_link</child>
            <axis>
                <xyz>0 1 0</xyz>
                <limit>
                    <lower>-10000000000000000</lower>
                    <upper>10000000000000000</upper>
                </limit>
                <dynamics>
                    <spring_reference>0</spring_reference>
                    <spring_stiffness>0</spring_stiffness>
                </dynamics>
            </axis>
            <physics>
                <ode>
                    <limit>
                        <cfm>0</cfm>
                        <erp>0.20000000000000001</erp>
                    </limit>
                </ode>
            </physics>
        </joint>
        <link name='rear_left_wheel_link'>
            <pose relative_to='rear_left_wheel'>0 0 0 0 0 0</pose>
            <inertial>
                <pose>0 0 0 0 0 0</pose>
                <mass>0.5</mass>
                <inertia>
                    <ixx>0.01055</ixx>
                    <ixy>0</ixy>
                    <ixz>0</ixz>
                    <iyy>0.00075000000000000002</iyy>
                    <iyz>0</iyz>
                    <izz>0.01055</izz>
                </inertia>
            </inertial>
            <collision name='rear_left_wheel_link_collision'>
                <pose>0 0.0225 0 1.57 0 0</pose>
                <geometry>
                    <cylinder>
                        <length>0.044999999999999998</length>
                        <radius>0.044999999999999998</radius>
                    </cylinder>
                </geometry>
            </collision>
            <visual name='rear_left_wheel_link_visual'>
                <pose>0 0 0 0 0 0</pose>
                <geometry>
                    <mesh>
                        <scale>1 1 1</scale>
                        <uri>meshes/limo_wheel.dae</uri>
                    </mesh>
                </geometry>
            </visual>
        </link>
        <joint name='rear_right_wheel' type='revolute'>
            <pose relative_to='base_footprint'>-0.1 -0.065 0.04999999999999999 3.14159 0 0</pose>
            <parent>base_footprint</parent>
            <child>rear_right_wheel_link</child>
            <axis>
                <xyz>0 -1 0</xyz>
                <limit>
                    <lower>-10000000000000000</lower>
                    <upper>10000000000000000</upper>
                </limit>
                <dynamics>
                    <spring_reference>0</spring_reference>
                    <spring_stiffness>0</spring_stiffness>
                </dynamics>
            </axis>
            <physics>
                <ode>
                    <limit>
                        <cfm>0</cfm>
                        <erp>0.20000000000000001</erp>
                    </limit>
                </ode>
            </physics>
        </joint>
        <link name='rear_right_wheel_link'>
            <pose relative_to='rear_right_wheel'>0 0 0 0 0 0</pose>
            <inertial>
                <pose>0 0 0 0 0 0</pose>
                <mass>0.5</mass>
                <inertia>
                    <ixx>0.01055</ixx>
                    <ixy>0</ixy>
                    <ixz>0</ixz>
                    <iyy>0.00075000000000000002</iyy>
                    <iyz>0</iyz>
                    <izz>0.01055</izz>
                </inertia>
            </inertial>
            <collision name='rear_right_wheel_link_collision'>
                <pose>0 0.0225 0 1.57 0 0</pose>
                <geometry>
                    <cylinder>
                        <length>0.044999999999999998</length>
                        <radius>0.044999999999999998</radius>
                    </cylinder>
                </geometry>
            </collision>
            <visual name='rear_right_wheel_link_visual'>
                <pose>0 0 0 0 0 0</pose>
                <geometry>
                    <mesh>
                        <scale>1 1 1</scale>
                        <uri>meshes/limo_wheel.dae</uri>
                    </mesh>
                </geometry>
            </visual>
        </link>
        <plugin filename="ignition-gazebo-diff-drive-system" name="ignition::gazebo::systems::DiffDrive">
            <topic>limo/cmd_vel</topic>
            <odom_topic>limo/odom</odom_topic>
            <left_joint>front_left_wheel</left_joint>
            <left_joint>rear_left_wheel</left_joint>
            <right_joint>front_right_wheel</right_joint>
            <right_joint>rear_right_wheel</right_joint>
            <wheel_separation>0.172</wheel_separation>
            <wheel_radius>0.045</wheel_radius>
            <!--max_linear_acceleration>1</max_linear_acceleration>
            <min_linear_acceleration>-1</min_linear_acceleration>
            <max_angular_acceleration>2</max_angular_acceleration>
            <min_angular_acceleration>-2</min_angular_acceleration>
            <max_linear_velocity>0.5</max_linear_velocity>
            <min_linear_velocity>-0.5</min_linear_velocity>
            <max_angular_velocity>1</max_angular_velocity>
            <min_angular_velocity>-1</min_angular_velocity-->
        </plugin>
        <frame name='depth_camera_to_camera_joint' attached_to='depth_camera_link'>
            <pose>0 0 0 -1.57079 -0 -1.57079</pose>
        </frame>
        <frame name='depth_link' attached_to='depth_camera_to_camera_joint'/>
        <frame name='depth_camera_joint' attached_to='base_link'>
            <pose>0.084 0 0.03 0 -0 0</pose>
        </frame>
        <frame name='depth_camera_link' attached_to='depth_camera_joint'/>
        <frame name='imu_joint' attached_to='base_link'>
            <pose>0 0 -0.1 0 -0 0</pose>
        </frame>
        <frame name='imu_link' attached_to='imu_joint'/>
        <frame name='inertial_joint' attached_to='base_link'>
            <pose>0 0 0 0 -0 0</pose>
        </frame>
        <frame name='inertial_link' attached_to='inertial_joint'/>
        <frame name='laser_joint' attached_to='base_link'>
            <pose>0.103 0 -0.034 0 -0 0</pose>
        </frame>
        <frame name='laser_link' attached_to='laser_joint'/>
        <frame name='base_joint' attached_to='base_footprint'>
            <pose>0 0 0.15 0 -0 0</pose>
        </frame>
        <frame name='base_link' attached_to='base_joint'/>
    </model>
</sdf>
